[Wed Mar 12 03:42:04 2014] [error] [client 184.58.162.245] mod_wsgi (pid=7134): Exception occurred processing WSGI script '/srv/my_project/app/conf/apache/django.wsgi'.
[Wed Mar 12 03:42:04 2014] [error] [client 184.58.162.245] Traceback (most recent call last):
[Wed Mar 12 03:42:04 2014] [error] [client 184.58.162.245]   File "/srv/my_project/venv/lib/python2.7/site-packages/django/core/handlers/wsgi.py", line 206, in __call__
[Wed Mar 12 03:42:04 2014] [error] [client 184.58.162.245]     response = self.get_response(request)
[Wed Mar 12 03:42:04 2014] [error] [client 184.58.162.245]   File "/srv/my_project/venv/lib/python2.7/site-packages/django/core/handlers/base.py", line 196, in get_response
[Wed Mar 12 03:42:04 2014] [error] [client 184.58.162.245]     response = self.handle_uncaught_exception(request, resolver, sys.exc_info())
[Wed Mar 12 03:42:04 2014] [error] [client 184.58.162.245]   File "/srv/my_project/venv/lib/python2.7/site-packages/django/core/handlers/base.py", line 234, in handle_uncaught_exception
[Wed Mar 12 03:42:04 2014] [error] [client 184.58.162.245]     if resolver.urlconf_module is None:
[Wed Mar 12 03:42:04 2014] [error] [client 184.58.162.245]   File "/srv/my_project/venv/lib/python2.7/site-packages/django/core/urlresolvers.py", line 341, in urlconf_module
[Wed Mar 12 03:42:04 2014] [error] [client 184.58.162.245]     self._urlconf_module = import_module(self.urlconf_name)
[Wed Mar 12 03:42:04 2014] [error] [client 184.58.162.245]   File "/srv/my_project/venv/lib/python2.7/site-packages/django/utils/importlib.py", line 40, in import_module
[Wed Mar 12 03:42:04 2014] [error] [client 184.58.162.245]     __import__(name)
[Wed Mar 12 03:42:04 2014] [error] [client 184.58.162.245]   File "/srv/my_project/app/webapp/webapp/urls.py", line 3, in <module>
[Wed Mar 12 03:42:04 2014] [error] [client 184.58.162.245]     from webapp.views import current_time,index,dr,hello, lljhb,llchb,xjjjhb,xjjchb,dealin,cgin,cginv,cgckb, My_Homepage_view#, search_papers
[Wed Mar 12 03:42:04 2014] [error] [client 184.58.162.245]   File "/srv/my_project/app/webapp/webapp/views.py", line 75
[Wed Mar 12 03:42:04 2014] [error] [client 184.58.162.245]     https://docs.google.com/spreadsheets/d/1MLuuPcB5Of71uXa-Evwyh0--AZxcZjzsKQbf71vw_0I/edit?usp=sharing
[Wed Mar 12 03:42:04 2014] [error] [client 184.58.162.245]          ^
[Wed Mar 12 03:42:04 2014] [error] [client 184.58.162.245] SyntaxError: invalid syntax
[Wed Mar 12 03:42:05 2014] [error] [client 184.58.162.245] File does not exist: /srv/my_project/app/webapp/site_media/favicon.ico
